Workbook

Sheet Claude Log
A1: Turn # | B1: Date | C1: User Request | D1: Action Taken | E1: Details | F1: Outcome
A2: 1 | B2: 46249 | C2: Populate Log Abstract cols A-F (FROM/TO/Voyage/Departure/Arrival/Leg Purpose) by matching each row's noon-time date against passages in 'Passages List' B:G. | D2: Wrote INDEX/MATCH formulas in Log Abstract A2:F351 keyed on noon time (col H). | E2: Formula: =IF($H2="","",INDEX('Passages List'!B$3:B$65,MATCH($H2,'Passages List'!$E$3:$E$65,1))) copied across A:F and down to row 351. Approximate MATCH on sorted DEPARTURE column places each noon time in its passage window. D:E formatted as dates to match noon-time col. | F2: 351 rows populated, 0 formula errors. Arrival reports map to port-stay rows, departure reports to new legs.

Sheet Vessel Details
A1: Vessel | B1: AMNS POLAR
A2: IMO number | B2: 9521813
A3: Year built | B3: 40984
A4: Vessel category | B4: General cargo ship (<20,000dwt)
A5: DWT | B5: 19560
A6: GT | B6: 13579
A7: Ice class | B7: yes
A8: Flag | B8: IN
A9: EEDI/EEXI | B9: N/A

Sheet Emissions KPIs
A1: CII | D1: AER
A2: 10.68 | B2: C | C2: [gCO2/(dwt*nm)] | D2: 10.68 | E2: gCO2/(dwt*nm)

Sheet Summary
A1: Period (from, to) | B1: 46023 | C1: 46249
B2: CII/AER
A3: Total distance (nm) | B3: 33864
A4: Total time (hrs) | B4: 5435
A5: Total fuel consumed (mt/kWh) | B5: 2243.41
A6: MGO | B6: 112.91
A7: LFO | B7: 2130.5
A8: Total Emissions (t CO2/t CO2e) | B8: 7075.19

Sheet Correction and Gaps
A1: Year | B1: Date (from) | C1: Date (to) | D1: Distance (nm) | E1: CO2 (mt) | F1: Total fuel cons. (mt)
A3: Total remaining data gaps: | B3: 0 days

Sheet Passages List
J1: ENERGY SOURCES | K1: EMISSIONS
B2: FROM | C2: TO | D2: VOYAGE NUMBER | E2: DEPARTURE [UTC] | F2: ARRIVAL [UTC] | G2: LEG PURPOSE | H2: Distance [nm] | I2: Cargo [t] | J2: Total energy [MJ] | K2: CII/AER [t] | L2: CII | M2: AER
A3: 1 | B3: Hazira Port (Surat) Hbr (INHZA) | C3: Chennai (ex Madras) (INMAA) | D3: 040 L | E3: 46019.654 | F3: 46026.492 | G3: Cargo | H3: 1681 | I3: 18155 | K3: 347.96 | L3: B | M3: 10.58
A4: PS | C4: Chennai (ex Madras) (INMAA) | D4: 040 L | E4: 46026.492 | F4: 46028.029 | G4: Cargo operations | H4: 0 | I4: 0 | K4: 18.72 | L4: -
A5: 3 | B5: Chennai (ex Madras) (INMAA) | C5: South Hbr (INMUN) | D5: 041 B | E5: 46028.029 | F5: 46034.704 | G5: Ballast | H5: 1862 | I5: 0 | K5: 321.82 | L5: A | M5: 8.84
A6: PS | C6: South Hbr (INMUN) | D6: 041 B | E6: 46034.704 | F6: 46038.029 | G6: Cargo operations | H6: 6 | I6: 18000 | K6: 37.63 | L6: E | M6: 320.62
A7: 5 | B7: South Hbr (INMUN) | C7: Northern Arm (INVTZ) | D7: 041 L | E7: 46038.029 | F7: 46046.479 | G7: Cargo | H7: 2141 | I7: 18000 | K7: 427.37 | L7: B | M7: 10.2
A8: PS | C8: Northern Arm (INVTZ) | D8: 041 L | E8: 46046.479 | F8: 46047.696 | G8: Cargo operations | H8: 0 | I8: 6000 | K8: 13.18 | L8: -
A9: 7 | B9: Northern Arm (INVTZ) | C9: Paradip Port Hbr (INPPT) | D9: 041 L | E9: 46047.696 | F9: 46048.633 | G9: Cargo | H9: 254 | I9: 6000 | K9: 48.54 | L9: B | M9: 9.78
A10: PS | C10: Paradip Port Hbr (INPPT) | D10: 041 L | E10: 46048.633 | F10: 46049.967 | G10: Cargo operations | H10: 10 | I10: 0 | K10: 18.07 | L10: E | M10: 89.71
A11: 9 | B11: Paradip Port Hbr (INPPT) | C11: Hazira Port (Surat) Hbr (INHZA) | D11: 042 | E11: 46049.967 | F11: 46050.037 | G11: Cargo | H11: 7 | I11: 0 | K11: 3.95 | L11: E | M11: 27.64
A12: PS | C12: Hazira Port (Surat) Hbr (INHZA) | D12: 042 | E12: 46050.037 | F12: 46050.892 | G12: No cargo operations | H12: 0 | I12: 0 | K12: 8.89 | L12: -
A13: 11 | B13: Paradip Port Hbr (INPPT) | C13: Paradip Port Hbr (INPPT) | D13: 042 | E13: 46050.892 | F13: 46051.217 | G13: Ballast | H13: 15 | I13: 0 | K13: 8.22 | L13: E | M13: 28.98
A14: PS | C14: Paradip Port Hbr (INPPT) | D14: 042 | E14: 46051.217 | F14: 46052.104 | G14: No cargo operations | H14: 0 | I14: 18600 | K14: 9.68 | L14: -
A15: 13 | B15: Paradip Port Hbr (INPPT) | C15: Hazira Port (Surat) Hbr (INHZA) | D15: 042 L | E15: 46052.104 | F15: 46063.196 | G15: Cargo | H15: 2110 | I15: 18600 | K15: 441.33 | L15: C | M15: 10.7
A16: PS | C16: Hazira Port (Surat) Hbr (INHZA) | D16: 042 L | E16: 46063.196 | F16: 46063.617 | G16: Cargo operations | H16: 0 | I16: 0 | K16: 3.97 | L16: -
A17: 15 | B17: Hazira Port (Surat) Hbr (INHZA) | C17: Hazira Port (Surat) Hbr (INHZA) | D17: 043 B | E17: 46063.617 | F17: 46067.4 | G17: Ballast | H17: 109 | I17: 0 | K17: 46.05 | L17: E | M17: 21.6
A18: PS | C18: Hazira Port (Surat) Hbr (INHZA) | D18: 043 B | E18: 46067.4 | F18: 46069.812 | G18: Cargo operations | H18: 0 | I18: 12536 | K18: 26.36 | L18: -
A19: 17 | B19: Hazira Port (Surat) Hbr (INHZA) | C19: New Mangalore (INNML) | D19: 043 L | E19: 46069.812 | F19: 46071.887 | G19: Cargo | H19: 541 | I19: 12536 | K19: 94.56 | L19: A | M19: 8.93
A20: PS | C20: New Mangalore (INNML) | D20: 043 L | E20: 46071.887 | F20: 46072.579 | G20: Cargo operations | H20: 0 | I20: 10165 | K20: 8.25 | L20: -
A21: 19 | B21: New Mangalore (INNML) | C21: Chennai (ex Madras) (INMAA) | D21: 043 L | E21: 46072.579 | F21: 46076.983 | G21: Cargo | H21: 1155 | I21: 10165 | K21: 202.34 | L21: A | M21: 8.96
A22: PS | C22: Chennai (ex Madras) (INMAA) | D22: 043 L | E22: 46076.983 | F22: 46078.325 | G22: Cargo operations | H22: 0 | I22: 0 | K22: 14.92 | L22: -
A23: 21 | B23: Chennai (ex Madras) (INMAA) | C23: Hazira Port (Surat) Hbr (INHZA) | D23: 044 B | E23: 46078.325 | F23: 46085.471 | G23: Ballast | H23: 1633 | I23: 0 | K23: 279.61 | L23: A | M23: 8.75
A24: PS | C24: Hazira Port (Surat) Hbr (INHZA) | D24: 044 B | E24: 46085.471 | F24: 46087.938 | G24: Cargo operations | H24: 0 | I24: 9018 | K24: 26.11 | L24: -
A25: 23 | B25: Hazira Port (Surat) Hbr (INHZA) | C25: Pir Pau (INBOM) | D25: 044 L | E25: 46087.938 | F25: 46088.904 | G25: Cargo | H25: 142 | I25: 9018 | K25: 24.28 | L25: A | M25: 8.72
A26: PS | C26: Pir Pau (INBOM) | D26: 044 L | E26: 46088.904 | F26: 46090.099 | G26: Cargo operations | H26: 0 | I26: 0 | K26: 10.48 | L26: -
A27: 25 | B27: Pir Pau (INBOM) | C27: Hazira Port (Surat) Hbr (INHZA) | D27: 45 B | E27: 46090.099 | F27: 46090.892 | G27: Ballast | H27: 156 | I27: 0 | K27: 25.21 | L27: A | M27: 8.26
A28: PS | C28: Hazira Port (Surat) Hbr (INHZA) | D28: 45 B | E28: 46090.892 | F28: 46093.104 | G28: Cargo operations | H28: 0 | I28: 11928 | K28: 24.42 | L28: -
A29: 27 | B29: Hazira Port (Surat) Hbr (INHZA) | C29: New Mangalore (INNML) | D29: 45 L | E29: 46093.104 | F29: 46095.238 | G29: Cargo | H29: 539 | I29: 11928 | K29: 94.07 | L29: A | M29: 8.92
A30: PS | C30: New Mangalore (INNML) | D30: 45 L | E30: 46095.238 | F30: 46101.417 | G30: Cargo operations | H30: 1146 | I30: 9422 | K30: 210.04 | L30: B | M30: 9.37
A31: 29 | B31: Chennai (ex Madras) (INMAA) | C31: Hazira Port (Surat) Hbr (INHZA) | D31: 46B | E31: 46101.417 | F31: 46109.842 | G31: Ballast | H31: 1677 | I31: 0 | K31: 307.16 | L31: B | M31: 9.36
A32: PS | C32: Hazira Port (Surat) Hbr (INHZA) | D32: 46B | E32: 46109.842 | F32: 46113.354 | G32: Cargo operations | H32: 0 | I32: 14000 | K32: 38.13 | L32: -
A33: 31 | B33: Hazira Port (Surat) Hbr (INHZA) | C33: Pir Pau (INBOM) | D33: 046 L | E33: 46113.354 | F33: 46120.908 | G33: Cargo | H33: 194 | I33: 14000 | K33: 95.04 | L33: E | M33: 25.02
A34: PS | C34: Pir Pau (INBOM) | D34: 046 L | E34: 46120.908 | F34: 46121.321 | G34: Cargo operations | H34: 0 | I34: 11307 | K34: 4.09 | L34: -
A35: 33 | B35: Pir Pau (INBOM) | C35: New Mangalore (INNML) | D35: 46L | E35: 46121.321 | F35: 46123.008 | G35: Cargo | H35: 429 | I35: 11307 | K35: 83.91 | L35: B | M35: 10.01
A36: PS | C36: New Mangalore (INNML) | D36: 46L | E36: 46123.008 | F36: 46123.733 | G36: Cargo operations | H36: 0 | I36: 9320 | K36: 7.82 | L36: -
A37: 35 | B37: New Mangalore (INNML) | C37: Chennai (ex Madras) (INMAA) | D37: 46L | E37: 46123.733 | F37: 46128.075 | G37: Cargo | H37: 1156 | I37: 9320 | K37: 205.86 | L37: A | M37: 9.1
A38: PS | C38: Chennai (ex Madras) (INMAA) | D38: 46L | E38: 46128.075 | F38: 46129.215 | G38: Cargo operations | H38: 0 | I38: 0 | K38: 13.12 | L38: -
A39: 37 | B39: Chennai (ex Madras) (INMAA) | C39: Hazira Port (Surat) Hbr (INHZA) | D39: 47B | E39: 46129.215 | F39: 46136.604 | G39: Ballast | H39: 1643 | I39: 0 | K39: 305.66 | L39: B | M39: 9.51
A40: PS | C40: Hazira Port (Surat) Hbr (INHZA) | D40: 47B | E40: 46136.604 | F40: 46139.204 | G40: Cargo operations | H40: 0 | I40: 14085 | K40: 29.33 | L40: -
...

Sheet Log Abstract
A1: FROM | B1: TO | C1: DEPARTURE [UTC] | D1: ARRIVAL [UTC] | E1: LEG PURPOSE | G1: NOON TIME | H1: LAT | I1: LON | J1: VOYAGE NUMBER | K1: Event | L1: TIME SINCE LAST REPORT [H] | M1: DISTANCE [NM] | N1: CARGO TOTAL MASS | O1: LFO [MT] | P1: MGO [MT]
A2: =IF($G2="","",INDEX('Passages List'!B$3:B$65,MATCH($G2,'Passages List'!$E$3:$E$65,1))) -> Paradip Port Hbr (INPPT) | B2: =IF($G2="","",INDEX('Passages List'!C$3:C$65,MATCH($G2,'Passages List'!$E$3:$E$65,1))) -> Hazira Port (Surat) Hbr (INHZA) | C2: =IF($G2="","",INDEX('Passages List'!E$3:E$65,MATCH($G2,'Passages List'!$E$3:$E$65,1))) -> 46052.104 | D2: =IF($G2="","",INDEX('Passages List'!F$3:F$65,MATCH($G2,'Passages List'!$E$3:$E$65,1))) -> 46063.196 | E2: =IF($G2="","",INDEX('Passages List'!G$3:G$65,MATCH($G2,'Passages List'!$E$3:$E$65,1))) -> Cargo | F2: Position report | G2: 46052.188 | H2: 20° 07.94' N | I2: 86° 52.03' E | J2: 42 L | K2: COSP | L2: 02:00 | M2: 16 | O2: 1.1 | P2: 0.1
A3: =IF($G3="","",INDEX('Passages List'!B$3:B$65,MATCH($G3,'Passages List'!$E$3:$E$65,1))) -> Paradip Port Hbr (INPPT) | B3: =IF($G3="","",INDEX('Passages List'!C$3:C$65,MATCH($G3,'Passages List'!$E$3:$E$65,1))) -> Hazira Port (Surat) Hbr (INHZA) | C3: =IF($G3="","",INDEX('Passages List'!E$3:E$65,MATCH($G3,'Passages List'!$E$3:$E$65,1))) -> 46052.104 | D3: =IF($G3="","",INDEX('Passages List'!F$3:F$65,MATCH($G3,'Passages List'!$E$3:$E$65,1))) -> 46063.196 | E3: =IF($G3="","",INDEX('Passages List'!G$3:G$65,MATCH($G3,'Passages List'!$E$3:$E$65,1))) -> Cargo | F3: Position report | G3: 46052.271 | H3: 19° 46.25' N | I3: 86° 30.32' E | J3: 42 L | K3: Noon At Sea | L3: 02:00 | M3: 23 | O3: 1.3 | P3: 0.1
A4: =IF($G4="","",INDEX('Passages List'!B$3:B$65,MATCH($G4,'Passages List'!$E$3:$E$65,1))) -> Paradip Port Hbr (INPPT) | B4: =IF($G4="","",INDEX('Passages List'!C$3:C$65,MATCH($G4,'Passages List'!$E$3:$E$65,1))) -> Hazira Port (Surat) Hbr (INHZA) | C4: =IF($G4="","",INDEX('Passages List'!E$3:E$65,MATCH($G4,'Passages List'!$E$3:$E$65,1))) -> 46052.104 | D4: =IF($G4="","",INDEX('Passages List'!F$3:F$65,MATCH($G4,'Passages List'!$E$3:$E$65,1))) -> 46063.196 | E4: =IF($G4="","",INDEX('Passages List'!G$3:G$65,MATCH($G4,'Passages List'!$E$3:$E$65,1))) -> Cargo | F4: Position report | G4: 46053.271 | H4: 15° 35.82' N | I4: 85° 18.87' E | J4: 42 L | K4: Noon At Sea | L4: 24:00 | M4: 264 | O4: 16.1 | P4: 0.2
A5: =IF($G5="","",INDEX('Passages List'!B$3:B$65,MATCH($G5,'Passages List'!$E$3:$E$65,1))) -> Paradip Port Hbr (INPPT) | B5: =IF($G5="","",INDEX('Passages List'!C$3:C$65,MATCH($G5,'Passages List'!$E$3:$E$65,1))) -> Hazira Port (Surat) Hbr (INHZA) | C5: =IF($G5="","",INDEX('Passages List'!E$3:E$65,MATCH($G5,'Passages List'!$E$3:$E$65,1))) -> 46052.104 | D5: =IF($G5="","",INDEX('Passages List'!F$3:F$65,MATCH($G5,'Passages List'!$E$3:$E$65,1))) -> 46063.196 | E5: =IF($G5="","",INDEX('Passages List'!G$3:G$65,MATCH($G5,'Passages List'!$E$3:$E$65,1))) -> Cargo | F5: Position report | G5: 46054.271 | H5: 11° 44.50' N | I5: 83° 56.01' E | J5: 42 L | K5: Noon At Sea | L5: 24:00 | M5: 244 | O5: 16.1 | P5: 0.2
A6: =IF($G6="","",INDEX('Passages List'!B$3:B$65,MATCH($G6,'Passages List'!$E$3:$E$65,1))) -> Paradip Port Hbr (INPPT) | B6: =IF($G6="","",INDEX('Passages List'!C$3:C$65,MATCH($G6,'Passages List'!$E$3:$E$65,1))) -> Hazira Port (Surat) Hbr (INHZA) | C6: =IF($G6="","",INDEX('Passages List'!E$3:E$65,MATCH($G6,'Passages List'!$E$3:$E$65,1))) -> 46052.104 | D6: =IF($G6="","",INDEX('Passages List'!F$3:F$65,MATCH($G6,'Passages List'!$E$3:$E$65,1))) -> 46063.196 | E6: =IF($G6="","",INDEX('Passages List'!G$3:G$65,MATCH($G6,'Passages List'!$E$3:$E$65,1))) -> Cargo | F6: Position report | G6: 46055.271 | H6: 7° 46.98' N | I6: 82° 32.12' E | J6: 42 L | K6: Noon At Sea | L6: 24:00 | M6: 251 | O6: 16.1 | P6: 0.2
A7: =IF($G7="","",INDEX('Passages List'!B$3:B$65,MATCH($G7,'Passages List'!$E$3:$E$65,1))) -> Paradip Port Hbr (INPPT) | B7: =IF($G7="","",INDEX('Passages List'!C$3:C$65,MATCH($G7,'Passages List'!$E$3:$E$65,1))) -> Hazira Port (Surat) Hbr (INHZA) | C7: =IF($G7="","",INDEX('Passages List'!E$3:E$65,MATCH($G7,'Passages List'!$E$3:$E$65,1))) -> 46052.104 | D7: =IF($G7="","",INDEX('Passages List'!F$3:F$65,MATCH($G7,'Passages List'!$E$3:$E$65,1))) -> 46063.196 | E7: =IF($G7="","",INDEX('Passages List'!G$3:G$65,MATCH($G7,'Passages List'!$E$3:$E$65,1))) -> Cargo | F7: Position report | G7: 46056.271 | H7: 6° 18.91' N | I7: 79° 19.54' E | J7: 42 L | K7: Noon At Sea | L7: 24:00 | M7: 271 | O7: 16.1 | P7: 0.2
A8: =IF($G8="","",INDEX('Passages List'!B$3:B$65,MATCH($G8,'Passages List'!$E$3:$E$65,1))) -> Paradip Port Hbr (INPPT) | B8: =IF($G8="","",INDEX('Passages List'!C$3:C$65,MATCH($G8,'Passages List'!$E$3:$E$65,1))) -> Hazira Port (Surat) Hbr (INHZA) | C8: =IF($G8="","",INDEX('Passages List'!E$3:E$65,MATCH($G8,'Passages List'!$E$3:$E$65,1))) -> 46052.104 | D8: =IF($G8="","",INDEX('Passages List'!F$3:F$65,MATCH($G8,'Passages List'!$E$3:$E$65,1))) -> 46063.196 | E8: =IF($G8="","",INDEX('Passages List'!G$3:G$65,MATCH($G8,'Passages List'!$E$3:$E$65,1))) -> Cargo | F8: Position report | G8: 46057.271 | H8: 8° 46.22' N | I8: 76° 00.29' E | J8: 42 L | K8: Noon At Sea | L8: 24:00 | M8: 248 | O8: 16.1 | P8: 0.2
A9: =IF($G9="","",INDEX('Passages List'!B$3:B$65,MATCH($G9,'Passages List'!$E$3:$E$65,1))) -> Paradip Port Hbr (INPPT) | B9: =IF($G9="","",INDEX('Passages List'!C$3:C$65,MATCH($G9,'Passages List'!$E$3:$E$65,1))) -> Hazira Port (Surat) Hbr (INHZA) | C9: =IF($G9="","",INDEX('Passages List'!E$3:E$65,MATCH($G9,'Passages List'!$E$3:$E$65,1))) -> 46052.104 | D9: =IF($G9="","",INDEX('Passages List'!F$3:F$65,MATCH($G9,'Passages List'!$E$3:$E$65,1))) -> 46063.196 | E9: =IF($G9="","",INDEX('Passages List'!G$3:G$65,MATCH($G9,'Passages List'!$E$3:$E$65,1))) -> Cargo | F9: Position report | G9: 46058.271 | H9: 12° 49.38' N | I9: 73° 44.19' E | J9: 42 L | K9: Noon At Sea | L9: 24:00 | M9: 277 | O9: 15.9 | P9: 0.2
A10: =IF($G10="","",INDEX('Passages List'!B$3:B$65,MATCH($G10,'Passages List'!$E$3:$E$65,1))) -> Paradip Port Hbr (INPPT) | B10: =IF($G10="","",INDEX('Passages List'!C$3:C$65,MATCH($G10,'Passages List'!$E$3:$E$65,1))) -> Hazira Port (Surat) Hbr (INHZA) | C10: =IF($G10="","",INDEX('Passages List'!E$3:E$65,MATCH($G10,'Passages List'!$E$3:$E$65,1))) -> 46052.104 | D10: =IF($G10="","",INDEX('Passages List'!F$3:F$65,MATCH($G10,'Passages List'!$E$3:$E$65,1))) -> 46063.196 | E10: =IF($G10="","",INDEX('Passages List'!G$3:G$65,MATCH($G10,'Passages List'!$E$3:$E$65,1))) -> Cargo | F10: Position report | G10: 46059.271 | H10: 17° 05.75' N | I10: 72° 39.92' E | J10: 42 L | K10: Noon At Sea | L10: 24:00 | M10: 269 | O10: 15.9 | P10: 0.2
A11: =IF($G11="","",INDEX('Passages List'!B$3:B$65,MATCH($G11,'Passages List'!$E$3:$E$65,1))) -> Paradip Port Hbr (INPPT) | B11: =IF($G11="","",INDEX('Passages List'!C$3:C$65,MATCH($G11,'Passages List'!$E$3:$E$65,1))) -> Hazira Port (Surat) Hbr (INHZA) | C11: =IF($G11="","",INDEX('Passages List'!E$3:E$65,MATCH($G11,'Passages List'!$E$3:$E$65,1))) -> 46052.104 | D11: =IF($G11="","",INDEX('Passages List'!F$3:F$65,MATCH($G11,'Passages List'!$E$3:$E$65,1))) -> 46063.196 | E11: =IF($G11="","",INDEX('Passages List'!G$3:G$65,MATCH($G11,'Passages List'!$E$3:$E$65,1))) -> Cargo | F11: Position report | G11: 46060.104 | H11: 20° 45.22' N | I11: 72° 39.92' E | J11: 42 L | K11: Noon At Sea | L11: 20:00 | M11: 220 | O11: 13.2 | P11: 0.2
A12: =IF($G12="","",INDEX('Passages List'!B$3:B$65,MATCH($G12,'Passages List'!$E$3:$E$65,1))) -> Paradip Port Hbr (INPPT) | B12: =IF($G12="","",INDEX('Passages List'!C$3:C$65,MATCH($G12,'Passages List'!$E$3:$E$65,1))) -> Hazira Port (Surat) Hbr (INHZA) | C12: =IF($G12="","",INDEX('Passages List'!E$3:E$65,MATCH($G12,'Passages List'!$E$3:$E$65,1))) -> 46052.104 | D12: =IF($G12="","",INDEX('Passages List'!F$3:F$65,MATCH($G12,'Passages List'!$E$3:$E$65,1))) -> 46063.196 | E12: =IF($G12="","",INDEX('Passages List'!G$3:G$65,MATCH($G12,'Passages List'!$E$3:$E$65,1))) -> Cargo | F12: Position report in port | G12: 46060.271 | H12: 20° 45.22' N | I12: 72° 39.92' E | J12: 42 L | K12: Noon At Sea | L12: 04:00 | M12: 9.7 | O12: 0.6 | P12: 0.3
A13: =IF($G13="","",INDEX('Passages List'!B$3:B$65,MATCH($G13,'Passages List'!$E$3:$E$65,1))) -> Paradip Port Hbr (INPPT) | B13: =IF($G13="","",INDEX('Passages List'!C$3:C$65,MATCH($G13,'Passages List'!$E$3:$E$65,1))) -> Hazira Port (Surat) Hbr (INHZA) | C13: =IF($G13="","",INDEX('Passages List'!E$3:E$65,MATCH($G13,'Passages List'!$E$3:$E$65,1))) -> 46052.104 | D13: =IF($G13="","",INDEX('Passages List'!F$3:F$65,MATCH($G13,'Passages List'!$E$3:$E$65,1))) -> 46063.196 | E13: =IF($G13="","",INDEX('Passages List'!G$3:G$65,MATCH($G13,'Passages List'!$E$3:$E$65,1))) -> Cargo | F13: Position report in port | G13: 46061.271 | H13: 20° 45.22' N | I13: 72° 39.92' E | J13: 42 L | K13: Noon At Sea | L13: 24:00 | M13: 2.9 | O13: 1.8 | P13: 1.5
A14: =IF($G14="","",INDEX('Passages List'!B$3:B$65,MATCH($G14,'Passages List'!$E$3:$E$65,1))) -> Paradip Port Hbr (INPPT) | B14: =IF($G14="","",INDEX('Passages List'!C$3:C$65,MATCH($G14,'Passages List'!$E$3:$E$65,1))) -> Hazira Port (Surat) Hbr (INHZA) | C14: =IF($G14="","",INDEX('Passages List'!E$3:E$65,MATCH($G14,'Passages List'!$E$3:$E$65,1))) -> 46052.104 | D14: =IF($G14="","",INDEX('Passages List'!F$3:F$65,MATCH($G14,'Passages List'!$E$3:$E$65,1))) -> 46063.196 | E14: =IF($G14="","",INDEX('Passages List'!G$3:G$65,MATCH($G14,'Passages List'!$E$3:$E$65,1))) -> Cargo | F14: Position report in port | G14: 46062.271 | H14: 20° 45.22' N | I14: 72° 39.92' E | J14: 42 L | K14: Noon At Sea | L14: 24:00 | O14: 1.6 | P14: 1.5
A15: =IF($G15="","",INDEX('Passages List'!B$3:B$65,MATCH($G15,'Passages List'!$E$3:$E$65,1))) | B15: =IF($G15="","",INDEX('Passages List'!C$3:C$65,MATCH($G15,'Passages List'!$E$3:$E$65,1))) -> Hazira Port (Surat) Hbr (INHZA) | C15: =IF($G15="","",INDEX('Passages List'!E$3:E$65,MATCH($G15,'Passages List'!$E$3:$E$65,1))) -> 46063.196 | D15: =IF($G15="","",INDEX('Passages List'!F$3:F$65,MATCH($G15,'Passages List'!$E$3:$E$65,1))) -> 46063.617 | E15: =IF($G15="","",INDEX('Passages List'!G$3:G$65,MATCH($G15,'Passages List'!$E$3:$E$65,1))) -> Cargo operations | F15: Arrival report | G15: 46063.196 | H15: 20° 53.00' N | I15: 72° 36.00' E | J15: 42 L | K15: EOSP | L15: 22:12 | M15: 14 | N15: 18600 | O15: 1.8 | P15: 1.3
A16: =IF($G16="","",INDEX('Passages List'!B$3:B$65,MATCH($G16,'Passages List'!$E$3:$E$65,1))) | B16: =IF($G16="","",INDEX('Passages List'!C$3:C$65,MATCH($G16,'Passages List'!$E$3:$E$65,1))) -> Hazira Port (Surat) Hbr (INHZA) | C16: =IF($G16="","",INDEX('Passages List'!E$3:E$65,MATCH($G16,'Passages List'!$E$3:$E$65,1))) -> 46063.196 | D16: =IF($G16="","",INDEX('Passages List'!F$3:F$65,MATCH($G16,'Passages List'!$E$3:$E$65,1))) -> 46063.617 | E16: =IF($G16="","",INDEX('Passages List'!G$3:G$65,MATCH($G16,'Passages List'!$E$3:$E$65,1))) -> Cargo operations | F16: Position report in port | G16: 46063.271 | H16: 20° 53.00' N | I16: 72° 36.00' E | J16: 42 L | L16: 01:48 | O16: 0.1 | P16: 0.1
A17: =IF($G17="","",INDEX('Passages List'!B$3:B$65,MATCH($G17,'Passages List'!$E$3:$E$65,1))) -> Hazira Port (Surat) Hbr (INHZA) | B17: =IF($G17="","",INDEX('Passages List'!C$3:C$65,MATCH($G17,'Passages List'!$E$3:$E$65,1))) -> Hazira Port (Surat) Hbr (INHZA) | C17: =IF($G17="","",INDEX('Passages List'!E$3:E$65,MATCH($G17,'Passages List'!$E$3:$E$65,1))) -> 46063.617 | D17: =IF($G17="","",INDEX('Passages List'!F$3:F$65,MATCH($G17,'Passages List'!$E$3:$E$65,1))) -> 46067.4 | E17: =IF($G17="","",INDEX('Passages List'!G$3:G$65,MATCH($G17,'Passages List'!$E$3:$E$65,1))) -> Ballast | F17: Departure report | G17: 46063.617 | H17: 20° 10.97' N | I17: 72° 21.20' E | J17: 43 B | K17: COSP | L17: 08:18 | O17: 0.5 | P17: 0.6
A18: =IF($G18="","",INDEX('Passages List'!B$3:B$65,MATCH($G18,'Passages List'!$E$3:$E$65,1))) -> Hazira Port (Surat) Hbr (INHZA) | B18: =IF($G18="","",INDEX('Passages List'!C$3:C$65,MATCH($G18,'Passages List'!$E$3:$E$65,1))) -> Hazira Port (Surat) Hbr (INHZA) | C18: =IF($G18="","",INDEX('Passages List'!E$3:E$65,MATCH($G18,'Passages List'!$E$3:$E$65,1))) -> 46063.617 | D18: =IF($G18="","",INDEX('Passages List'!F$3:F$65,MATCH($G18,'Passages List'!$E$3:$E$65,1))) -> 46067.4 | E18: =IF($G18="","",INDEX('Passages List'!G$3:G$65,MATCH($G18,'Passages List'!$E$3:$E$65,1))) -> Ballast | F18: Position report | G18: 46064.271 | H18: 20° 10.97' N | I18: 72° 21.20' E | J18: 43 B | K18: Noon At Sea | L18: 15:42 | M18: 42 | O18: 2.7 | P18: 0.8
A19: =IF($G19="","",INDEX('Passages List'!B$3:B$65,MATCH($G19,'Passages List'!$E$3:$E$65,1))) -> Hazira Port (Surat) Hbr (INHZA) | B19: =IF($G19="","",INDEX('Passages List'!C$3:C$65,MATCH($G19,'Passages List'!$E$3:$E$65,1))) -> Hazira Port (Surat) Hbr (INHZA) | C19: =IF($G19="","",INDEX('Passages List'!E$3:E$65,MATCH($G19,'Passages List'!$E$3:$E$65,1))) -> 46063.617 | D19: =IF($G19="","",INDEX('Passages List'!F$3:F$65,MATCH($G19,'Passages List'!$E$3:$E$65,1))) -> 46067.4 | E19: =IF($G19="","",INDEX('Passages List'!G$3:G$65,MATCH($G19,'Passages List'!$E$3:$E$65,1))) -> Ballast | F19: Position report | G19: 46065.271 | H19: 20° 02.51' N | I19: 72° 24.83' E | J19: 43 B | K19: Noon At Sea | L19: 24:00 | O19: 1.8 | P19: 1.4
A20: =IF($G20="","",INDEX('Passages List'!B$3:B$65,MATCH($G20,'Passages List'!$E$3:$E$65,1))) -> Hazira Port (Surat) Hbr (INHZA) | B20: =IF($G20="","",INDEX('Passages List'!C$3:C$65,MATCH($G20,'Passages List'!$E$3:$E$65,1))) -> Hazira Port (Surat) Hbr (INHZA) | C20: =IF($G20="","",INDEX('Passages List'!E$3:E$65,MATCH($G20,'Passages List'!$E$3:$E$65,1))) -> 46063.617 | D20: =IF($G20="","",INDEX('Passages List'!F$3:F$65,MATCH($G20,'Passages List'!$E$3:$E$65,1))) -> 46067.4 | E20: =IF($G20="","",INDEX('Passages List'!G$3:G$65,MATCH($G20,'Passages List'!$E$3:$E$65,1))) -> Ballast | F20: Position report in port | G20: 46066.271 | H20: 20° 52.64' N | I20: 72° 38.20' E | J20: 43 B | K20: Noon At Sea | L20: 24:00 | M20: 53 | O20: 2.5 | P20: 1.4
A21: =IF($G21="","",INDEX('Passages List'!B$3:B$65,MATCH($G21,'Passages List'!$E$3:$E$65,1))) -> Hazira Port (Surat) Hbr (INHZA) | B21: =IF($G21="","",INDEX('Passages List'!C$3:C$65,MATCH($G21,'Passages List'!$E$3:$E$65,1))) -> Hazira Port (Surat) Hbr (INHZA) | C21: =IF($G21="","",INDEX('Passages List'!E$3:E$65,MATCH($G21,'Passages List'!$E$3:$E$65,1))) -> 46063.617 | D21: =IF($G21="","",INDEX('Passages List'!F$3:F$65,MATCH($G21,'Passages List'!$E$3:$E$65,1))) -> 46067.4 | E21: =IF($G21="","",INDEX('Passages List'!G$3:G$65,MATCH($G21,'Passages List'!$E$3:$E$65,1))) -> Ballast | F21: Position report in port | G21: 46067.271 | H21: 20° 52.64' N | I21: 72° 38.20' E | J21: 43 B | K21: Noon At Sea | L21: 24:00 | O21: 1.7 | P21: 1.5
A22: =IF($G22="","",INDEX('Passages List'!B$3:B$65,MATCH($G22,'Passages List'!$E$3:$E$65,1))) | B22: =IF($G22="","",INDEX('Passages List'!C$3:C$65,MATCH($G22,'Passages List'!$E$3:$E$65,1))) -> Hazira Port (Surat) Hbr (INHZA) | C22: =IF($G22="","",INDEX('Passages List'!E$3:E$65,MATCH($G22,'Passages List'!$E$3:$E$65,1))) -> 46067.4 | D22: =IF($G22="","",INDEX('Passages List'!F$3:F$65,MATCH($G22,'Passages List'!$E$3:$E$65,1))) -> 46069.812 | E22: =IF($G22="","",INDEX('Passages List'!G$3:G$65,MATCH($G22,'Passages List'!$E$3:$E$65,1))) -> Cargo operations | F22: Arrival report | G22: 46067.4 | H22: 21° 05.14' N | I22: 72° 39.46' E | J22: 43 B | K22: EOSP | L22: 03:06 | M22: 14 | O22: 0.5 | P22: 0.2
A23: =IF($G23="","",INDEX('Passages List'!B$3:B$65,MATCH($G23,'Passages List'!$E$3:$E$65,1))) | B23: =IF($G23="","",INDEX('Passages List'!C$3:C$65,MATCH($G23,'Passages List'!$E$3:$E$65,1))) -> Hazira Port (Surat) Hbr (INHZA) | C23: =IF($G23="","",INDEX('Passages List'!E$3:E$65,MATCH($G23,'Passages List'!$E$3:$E$65,1))) -> 46067.4 | D23: =IF($G23="","",INDEX('Passages List'!F$3:F$65,MATCH($G23,'Passages List'!$E$3:$E$65,1))) -> 46069.812 | E23: =IF($G23="","",INDEX('Passages List'!G$3:G$65,MATCH($G23,'Passages List'!$E$3:$E$65,1))) -> Cargo operations | F23: Position report in port | G23: 46068.271 | H23: 21° 05.14' N | I23: 72° 39.46' E | J23: 43 B | L23: 20:54 | O23: 1.8 | P23: 1.3
A24: =IF($G24="","",INDEX('Passages List'!B$3:B$65,MATCH($G24,'Passages List'!$E$3:$E$65,1))) | B24: =IF($G24="","",INDEX('Passages List'!C$3:C$65,MATCH($G24,'Passages List'!$E$3:$E$65,1))) -> Hazira Port (Surat) Hbr (INHZA) | C24: =IF($G24="","",INDEX('Passages List'!E$3:E$65,MATCH($G24,'Passages List'!$E$3:$E$65,1))) -> 46067.4 | D24: =IF($G24="","",INDEX('Passages List'!F$3:F$65,MATCH($G24,'Passages List'!$E$3:$E$65,1))) -> 46069.812 | E24: =IF($G24="","",INDEX('Passages List'!G$3:G$65,MATCH($G24,'Passages List'!$E$3:$E$65,1))) -> Cargo operations | F24: Position report in port | G24: 46069.271 | H24: 21° 05.14' N | I24: 72° 39.46' E | J24: 43 B | L24: 24:00 | O24: 1.9 | P24: 1.5
A25: =IF($G25="","",INDEX('Passages List'!B$3:B$65,MATCH($G25,'Passages List'!$E$3:$E$65,1))) -> Hazira Port (Surat) Hbr (INHZA) | B25: =IF($G25="","",INDEX('Passages List'!C$3:C$65,MATCH($G25,'Passages List'!$E$3:$E$65,1))) -> New Mangalore (INNML) | C25: =IF($G25="","",INDEX('Passages List'!E$3:E$65,MATCH($G25,'Passages List'!$E$3:$E$65,1))) -> 46069.812 | D25: =IF($G25="","",INDEX('Passages List'!F$3:F$65,MATCH($G25,'Passages List'!$E$3:$E$65,1))) -> 46071.887 | E25: =IF($G25="","",INDEX('Passages List'!G$3:G$65,MATCH($G25,'Passages List'!$E$3:$E$65,1))) -> Cargo | F25: Departure report | G25: 46069.812 | H25: 21° 05.14' N | I25: 72° 36.49' E | J25: 43 L - 1 | L25: 13:00 | N25: 12535.9 | O25: 0.9 | P25: 0.9
A26: =IF($G26="","",INDEX('Passages List'!B$3:B$65,MATCH($G26,'Passages List'!$E$3:$E$65,1))) -> Hazira Port (Surat) Hbr (INHZA) | B26: =IF($G26="","",INDEX('Passages List'!C$3:C$65,MATCH($G26,'Passages List'!$E$3:$E$65,1))) -> New Mangalore (INNML) | C26: =IF($G26="","",INDEX('Passages List'!E$3:E$65,MATCH($G26,'Passages List'!$E$3:$E$65,1))) -> 46069.812 | D26: =IF($G26="","",INDEX('Passages List'!F$3:F$65,MATCH($G26,'Passages List'!$E$3:$E$65,1))) -> 46071.887 | E26: =IF($G26="","",INDEX('Passages List'!G$3:G$65,MATCH($G26,'Passages List'!$E$3:$E$65,1))) -> Cargo | F26: Position report | G26: 46069.875 | H26: 20° 57.82' N | I26: 72° 33.19' E | J26: 43 L - 1 | K26: COSP | L26: 01:30 | M26: 11.2 | O26: 0.7 | P26: 0.1
A27: =IF($G27="","",INDEX('Passages List'!B$3:B$65,MATCH($G27,'Passages List'!$E$3:$E$65,1))) -> Hazira Port (Surat) Hbr (INHZA) | B27: =IF($G27="","",INDEX('Passages List'!C$3:C$65,MATCH($G27,'Passages List'!$E$3:$E$65,1))) -> New Mangalore (INNML) | C27: =IF($G27="","",INDEX('Passages List'!E$3:E$65,MATCH($G27,'Passages List'!$E$3:$E$65,1))) -> 46069.812 | D27: =IF($G27="","",INDEX('Passages List'!F$3:F$65,MATCH($G27,'Passages List'!$E$3:$E$65,1))) -> 46071.887 | E27: =IF($G27="","",INDEX('Passages List'!G$3:G$65,MATCH($G27,'Passages List'!$E$3:$E$65,1))) -> Cargo | F27: Position report | G27: 46070.271 | H27: 19° 08.34' N | I27: 72° 27.76' E | J27: 43 L - 1 | K27: Noon At Sea | L27: 09:30 | M27: 112 | O27: 5.1 | P27: 0.1
A28: =IF($G28="","",INDEX('Passages List'!B$3:B$65,MATCH($G28,'Passages List'!$E$3:$E$65,1))) -> Hazira Port (Surat) Hbr (INHZA) | B28: =IF($G28="","",INDEX('Passages List'!C$3:C$65,MATCH($G28,'Passages List'!$E$3:$E$65,1))) -> New Mangalore (INNML) | C28: =IF($G28="","",INDEX('Passages List'!E$3:E$65,MATCH($G28,'Passages List'!$E$3:$E$65,1))) -> 46069.812 | D28: =IF($G28="","",INDEX('Passages List'!F$3:F$65,MATCH($G28,'Passages List'!$E$3:$E$65,1))) -> 46071.887 | E28: =IF($G28="","",INDEX('Passages List'!G$3:G$65,MATCH($G28,'Passages List'!$E$3:$E$65,1))) -> Cargo | F28: Position report | G28: 46071.271 | H28: 14° 49.63' N | I28: 73° 32.66' E | J28: 43 L - 1 | K28: Noon At Sea | L28: 24:00 | M28: 266 | O28: 15.9 | P28: 0.1
A29: =IF($G29="","",INDEX('Passages List'!B$3:B$65,MATCH($G29,'Passages List'!$E$3:$E$65,1))) -> Hazira Port (Surat) Hbr (INHZA) | B29: =IF($G29="","",INDEX('Passages List'!C$3:C$65,MATCH($G29,'Passages List'!$E$3:$E$65,1))) -> New Mangalore (INNML) | C29: =IF($G29="","",INDEX('Passages List'!E$3:E$65,MATCH($G29,'Passages List'!$E$3:$E$65,1))) -> 46069.812 | D29: =IF($G29="","",INDEX('Passages List'!F$3:F$65,MATCH($G29,'Passages List'!$E$3:$E$65,1))) -> 46071.887 | E29: =IF($G29="","",INDEX('Passages List'!G$3:G$65,MATCH($G29,'Passages List'!$E$3:$E$65,1))) -> Cargo | F29: Position report | G29: 46071.771 | H29: 12° 57.92' N | I29: 74° 29.21' E | J29: 43 L - 1 | K29: Noon At Sea | L29: 12:00 | M29: 132 | O29: 7 | P29: 0.1
A30: =IF($G30="","",INDEX('Passages List'!B$3:B$65,MATCH($G30,'Passages List'!$E$3:$E$65,1))) | B30: =IF($G30="","",INDEX('Passages List'!C$3:C$65,MATCH($G30,'Passages List'!$E$3:$E$65,1))) -> New Mangalore (INNML) | C30: =IF($G30="","",INDEX('Passages List'!E$3:E$65,MATCH($G30,'Passages List'!$E$3:$E$65,1))) -> 46071.887 | D30: =IF($G30="","",INDEX('Passages List'!F$3:F$65,MATCH($G30,'Passages List'!$E$3:$E$65,1))) -> 46072.579 | E30: =IF($G30="","",INDEX('Passages List'!G$3:G$65,MATCH($G30,'Passages List'!$E$3:$E$65,1))) -> Cargo operations | F30: Arrival report | G30: 46071.887 | H30: 12° 55.89' N | I30: 74° 49.03' E | J30: 43 L - 1 | K30: EOSP | L30: 02:48 | M30: 20 | N30: 12535.9 | O30: 0.7 | P30: 0.2
A31: =IF($G31="","",INDEX('Passages List'!B$3:B$65,MATCH($G31,'Passages List'!$E$3:$E$65,1))) | B31: =IF($G31="","",INDEX('Passages List'!C$3:C$65,MATCH($G31,'Passages List'!$E$3:$E$65,1))) -> New Mangalore (INNML) | C31: =IF($G31="","",INDEX('Passages List'!E$3:E$65,MATCH($G31,'Passages List'!$E$3:$E$65,1))) -> 46071.887 | D31: =IF($G31="","",INDEX('Passages List'!F$3:F$65,MATCH($G31,'Passages List'!$E$3:$E$65,1))) -> 46072.579 | E31: =IF($G31="","",INDEX('Passages List'!G$3:G$65,MATCH($G31,'Passages List'!$E$3:$E$65,1))) -> Cargo operations | F31: Position report in port | G31: 46072.271 | H31: 12° 55.89' N | I31: 74° 49.03' E | J31: 43 L - 1 | L31: 09:12 | O31: 0.8 | P31: 0.6
A32: =IF($G32="","",INDEX('Passages List'!B$3:B$65,MATCH($G32,'Passages List'!$E$3:$E$65,1))) -> New Mangalore (INNML) | B32: =IF($G32="","",INDEX('Passages List'!C$3:C$65,MATCH($G32,'Passages List'!$E$3:$E$65,1))) -> Chennai (ex Madras) (INMAA) | C32: =IF($G32="","",INDEX('Passages List'!E$3:E$65,MATCH($G32,'Passages List'!$E$3:$E$65,1))) -> 46072.579 | D32: =IF($G32="","",INDEX('Passages List'!F$3:F$65,MATCH($G32,'Passages List'!$E$3:$E$65,1))) -> 46076.983 | E32: =IF($G32="","",INDEX('Passages List'!G$3:G$65,MATCH($G32,'Passages List'!$E$3:$E$65,1))) -> Cargo | F32: Departure report | G32: 46072.579 | H32: 12° 55.89' N | I32: 74° 49.03' E | J32: 43 L - 2 | L32: 07:24 | N32: 10165.2 | O32: 0.7 | P32: 0.5
A33: =IF($G33="","",INDEX('Passages List'!B$3:B$65,MATCH($G33,'Passages List'!$E$3:$E$65,1))) -> New Mangalore (INNML) | B33: =IF($G33="","",INDEX('Passages List'!C$3:C$65,MATCH($G33,'Passages List'!$E$3:$E$65,1))) -> Chennai (ex Madras) (INMAA) | C33: =IF($G33="","",INDEX('Passages List'!E$3:E$65,MATCH($G33,'Passages List'!$E$3:$E$65,1))) -> 46072.579 | D33: =IF($G33="","",INDEX('Passages List'!F$3:F$65,MATCH($G33,'Passages List'!$E$3:$E$65,1))) -> 46076.983 | E33: =IF($G33="","",INDEX('Passages List'!G$3:G$65,MATCH($G33,'Passages List'!$E$3:$E$65,1))) -> Cargo | F33: Position report | G33: 46072.625 | H33: 12° 53.52' N | I33: 74° 44.64' E | J33: 43 L - 2 | K33: COSP | L33: 01:06 | M33: 7 | O33: 0.5 | P33: 0.1
A34: =IF($G34="","",INDEX('Passages List'!B$3:B$65,MATCH($G34,'Passages List'!$E$3:$E$65,1))) -> New Mangalore (INNML) | B34: =IF($G34="","",INDEX('Passages List'!C$3:C$65,MATCH($G34,'Passages List'!$E$3:$E$65,1))) -> Chennai (ex Madras) (INMAA) | C34: =IF($G34="","",INDEX('Passages List'!E$3:E$65,MATCH($G34,'Passages List'!$E$3:$E$65,1))) -> 46072.579 | D34: =IF($G34="","",INDEX('Passages List'!F$3:F$65,MATCH($G34,'Passages List'!$E$3:$E$65,1))) -> 46076.983 | E34: =IF($G34="","",INDEX('Passages List'!G$3:G$65,MATCH($G34,'Passages List'!$E$3:$E$65,1))) -> Cargo | F34: Position report | G34: 46073.271 | H34: 10° 10.90' N | I34: 75° 11.17' E | J34: 43 L - 2 | K34: Noon At Sea | L34: 15:30 | M34: 173 | O34: 9.6 | P34: 0.1
A35: =IF($G35="","",INDEX('Passages List'!B$3:B$65,MATCH($G35,'Passages List'!$E$3:$E$65,1))) -> New Mangalore (INNML) | B35: =IF($G35="","",INDEX('Passages List'!C$3:C$65,MATCH($G35,'Passages List'!$E$3:$E$65,1))) -> Chennai (ex Madras) (INMAA) | C35: =IF($G35="","",INDEX('Passages List'!E$3:E$65,MATCH($G35,'Passages List'!$E$3:$E$65,1))) -> 46072.579 | D35: =IF($G35="","",INDEX('Passages List'!F$3:F$65,MATCH($G35,'Passages List'!$E$3:$E$65,1))) -> 46076.983 | E35: =IF($G35="","",INDEX('Passages List'!G$3:G$65,MATCH($G35,'Passages List'!$E$3:$E$65,1))) -> Cargo | F35: Position report | G35: 46074.271 | H35: 6° 57.64' N | I35: 78° 13.14' E | J35: 43 L - 2 | K35: Noon At Sea | L35: 24:00 | M35: 272 | O35: 14.9 | P35: 0.1
A36: =IF($G36="","",INDEX('Passages List'!B$3:B$65,MATCH($G36,'Passages List'!$E$3:$E$65,1))) -> New Mangalore (INNML) | B36: =IF($G36="","",INDEX('Passages List'!C$3:C$65,MATCH($G36,'Passages List'!$E$3:$E$65,1))) -> Chennai (ex Madras) (INMAA) | C36: =IF($G36="","",INDEX('Passages List'!E$3:E$65,MATCH($G36,'Passages List'!$E$3:$E$65,1))) -> 46072.579 | D36: =IF($G36="","",INDEX('Passages List'!F$3:F$65,MATCH($G36,'Passages List'!$E$3:$E$65,1))) -> 46076.983 | E36: =IF($G36="","",INDEX('Passages List'!G$3:G$65,MATCH($G36,'Passages List'!$E$3:$E$65,1))) -> Cargo | F36: Position report | G36: 46075.271 | H36: 6° 25.03' N | I36: 81° 58.45' E | J36: 43 L - 2 | K36: Noon At Sea | L36: 24:00 | M36: 265 | O36: 14.9 | P36: 0.1
A37: =IF($G37="","",INDEX('Passages List'!B$3:B$65,MATCH($G37,'Passages List'!$E$3:$E$65,1))) -> New Mangalore (INNML) | B37: =IF($G37="","",INDEX('Passages List'!C$3:C$65,MATCH($G37,'Passages List'!$E$3:$E$65,1))) -> Chennai (ex Madras) (INMAA) | C37: =IF($G37="","",INDEX('Passages List'!E$3:E$65,MATCH($G37,'Passages List'!$E$3:$E$65,1))) -> 46072.579 | D37: =IF($G37="","",INDEX('Passages List'!F$3:F$65,MATCH($G37,'Passages List'!$E$3:$E$65,1))) -> 46076.983 | E37: =IF($G37="","",INDEX('Passages List'!G$3:G$65,MATCH($G37,'Passages List'!$E$3:$E$65,1))) -> Cargo | F37: Position report | G37: 46076.271 | H37: 10° 29.77' N | I37: 81° 28.36' E | J37: 43 L - 2 | K37: Noon At Sea | L37: 24:00 | M37: 259 | O37: 14.9 | P37: 0.1
A38: =IF($G38="","",INDEX('Passages List'!B$3:B$65,MATCH($G38,'Passages List'!$E$3:$E$65,1))) -> New Mangalore (INNML) | B38: =IF($G38="","",INDEX('Passages List'!C$3:C$65,MATCH($G38,'Passages List'!$E$3:$E$65,1))) -> Chennai (ex Madras) (INMAA) | C38: =IF($G38="","",INDEX('Passages List'!E$3:E$65,MATCH($G38,'Passages List'!$E$3:$E$65,1))) -> 46072.579 | D38: =IF($G38="","",INDEX('Passages List'!F$3:F$65,MATCH($G38,'Passages List'!$E$3:$E$65,1))) -> 46076.983 | E38: =IF($G38="","",INDEX('Passages List'!G$3:G$65,MATCH($G38,'Passages List'!$E$3:$E$65,1))) -> Cargo | F38: Position report | G38: 46076.867 | H38: 13° 00.55' N | I38: 80° 31.32' E | J38: 43 L - 2 | K38: Noon At Sea | L38: 14:18 | M38: 165 | O38: 7.9 | P38: 0.1
A39: =IF($G39="","",INDEX('Passages List'!B$3:B$65,MATCH($G39,'Passages List'!$E$3:$E$65,1))) | B39: =IF($G39="","",INDEX('Passages List'!C$3:C$65,MATCH($G39,'Passages List'!$E$3:$E$65,1))) -> Chennai (ex Madras) (INMAA) | C39: =IF($G39="","",INDEX('Passages List'!E$3:E$65,MATCH($G39,'Passages List'!$E$3:$E$65,1))) -> 46076.983 | D39: =IF($G39="","",INDEX('Passages List'!F$3:F$65,MATCH($G39,'Passages List'!$E$3:$E$65,1))) -> 46078.325 | E39: =IF($G39="","",INDEX('Passages List'!G$3:G$65,MATCH($G39,'Passages List'!$E$3:$E$65,1))) -> Cargo operations | F39: Arrival report | G39: 46076.983 | H39: 13° 05.21' N | I39: 80° 17.63' E | J39: 43 L - 2 | K39: EOSP | L39: 02:48 | M39: 14 | N39: 10165.2 | O39: 0.7 | P39: 0.2
A40: =IF($G40="","",INDEX('Passages List'!B$3:B$65,MATCH($G40,'Passages List'!$E$3:$E$65,1))) | B40: =IF($G40="","",INDEX('Passages List'!C$3:C$65,MATCH($G40,'Passages List'!$E$3:$E$65,1))) -> Chennai (ex Madras) (INMAA) | C40: =IF($G40="","",INDEX('Passages List'!E$3:E$65,MATCH($G40,'Passages List'!$E$3:$E$65,1))) -> 46076.983 | D40: =IF($G40="","",INDEX('Passages List'!F$3:F$65,MATCH($G40,'Passages List'!$E$3:$E$65,1))) -> 46078.325 | E40: =IF($G40="","",INDEX('Passages List'!G$3:G$65,MATCH($G40,'Passages List'!$E$3:$E$65,1))) -> Cargo operations | F40: Position report in port | G40: 46077.271 | H40: 13° 05.21' N | I40: 80° 17.63' E | J40: 43 L - 2 | L40: 06:54 | O40: 0.6 | P40: 0.4
...
